<?xml version="1.0" ?>
<!-- =================================================================================== -->
<!-- |    This document was autogenerated by xacro from /home/allen/finger/src/gripper/urdf/3fgripper.xacro | -->
<!-- |    EDITING THIS FILE BY HAND IS NOT RECOMMENDED                                 | -->
<!-- =================================================================================== -->
<robot name="3fgripper" xmlns:xacro="http://www.ros.org/wiki/xacro">
  <gazebo>
    <plugin filename="libgazebo_ros_control.so" name="gazebo_ros_control">
      <robotNamespace>/fingertest</robotNamespace>
      <robotSimType>gazebo_ros_control/DefaultRobotHWSim</robotSimType>
      <legacyModeNS>true</legacyModeNS>
    </plugin>
  </gazebo>
  <!-- <gazebo>
  <plugin name="finger_gazebo_ros_bumper_controller" filename="libgazebo_ros_bumper.so">
    <alwaysOn>true</alwaysOn>
    <updateRate>10</updateRate>
    <bumperTopicName>finger_bumper</bumperTopicName>
    <frameName>world</frameName>
  </plugin>
</gazebo> -->
  &gt; 
  
  <gazebo>
    <plugin filename="libgazebo_ros_control.so" name="gazebo_ros_control">
      <robotNamespace>/3fgripper</robotNamespace>
      <robotSimType>gazebo_ros_control/DefaultRobotHWSim</robotSimType>
      <legacyModeNS>true</legacyModeNS>
    </plugin>
  </gazebo>
  <link name="world"/>
  <link name="gripper_base_link">
    <inertial>
      <origin rpy="0 0 0" xyz="-0.0019571 1.9748E-05 0.052522"/>
      <mass value="0.088404"/>
      <inertia ixx="0.1" ixy="1.4704E-08" ixz="-2.4848E-07" iyy="0.1" iyz="3.2395E-09" izz="0.1"/>
    </inertial>
    <visual>
      <origin rpy="0 0 0" xyz="0 0 0"/>
      <geometry>
        <mesh filename="package://gripper_base/meshes/gripper_base_link.STL"/>
      </geometry>
      <material name="">
        <color rgba="0.79216 0.81961 0.93333 1"/>
      </material>
    </visual>
    <collision>
      <origin rpy="0 0 0" xyz="0 0 0"/>
      <geometry>
        <mesh filename="package://gripper_base/meshes/gripper_base_link.STL"/>
      </geometry>
    </collision>
  </link>
  <link name="l_finger_link">
    <inertial>
      <origin rpy="0 0 0" xyz="-0.0053798 -5.6205E-16 0.012857"/>
      <mass value="0.014765"/>
      <inertia ixx="0.1" ixy="-1.2909E-22" ixz="-3.1553E-22" iyy="0.1" iyz="1.1779E-23" izz="0.1"/>
    </inertial>
    <visual>
      <origin rpy="0 0 0" xyz="0 0 0"/>
      <geometry>
        <mesh filename="package://gripper_base/meshes/l_finger_link.STL"/>
      </geometry>
      <material name="">
        <color rgba="0.79216 0.81961 0.93333 1"/>
      </material>
    </visual>
    <collision>
      <origin rpy="0 0 0" xyz="0 0 0"/>
      <geometry>
        <mesh filename="package://gripper_base/meshes/l_finger_link.STL"/>
      </geometry>
    </collision>
  </link>
  <!-- <link name="world"/> -->
  <joint name="fixed123" type="fixed">
    <origin rpy="0 0 0" xyz="0 0 0"/>
    <parent link="world"/>
    <child link="gripper_base_link"/>
    <axis xyz="0 0 0"/>
  </joint>
  <joint name="l_finger_joint" type="continuous">
    <origin rpy="0 0 0" xyz="0 0.026 0.0565"/>
    <parent link="gripper_base_link"/>
    <child link="l_finger_link"/>
    <axis xyz="0 0 -1"/>
  </joint>
  <link name="r_finger_link">
    <inertial>
      <origin rpy="0 0 0" xyz="-0.0053798 -8.1532E-16 0.012857"/>
      <mass value="0.014765"/>
      <inertia ixx="0.1" ixy="1.8121E-21" ixz="-1.2879E-22" iyy="0.1" iyz="1.4405E-22" izz="0.1"/>
    </inertial>
    <visual>
      <origin rpy="0 0 0" xyz="0 0 0"/>
      <geometry>
        <mesh filename="package://gripper_base/meshes/r_finger_link.STL"/>
      </geometry>
      <material name="">
        <color rgba="0.79216 0.81961 0.93333 1"/>
      </material>
    </visual>
    <collision>
      <origin rpy="0 0 0" xyz="0 0 0"/>
      <geometry>
        <mesh filename="package://gripper_base/meshes/r_finger_link.STL"/>
      </geometry>
    </collision>
  </link>
  <joint name="r_finger_joint" type="continuous">
    <origin rpy="0 0 0" xyz="0 -0.026 0.0565"/>
    <parent link="gripper_base_link"/>
    <child link="r_finger_link"/>
    <!-- <axis
      xyz="0 0 -1" /> -->
    <axis xyz="0 0 1"/>
  </joint>
  <transmission name="tran1">
    <type>transmission_interface/SimpleTransmission</type>
    <joint name="l_finger_joint">
      <hardwareInterface>hardware_interface/EffortJointInterface</hardwareInterface>
    </joint>
    <actuator name="motor1">
      <hardwareInterface>hardware_interface/EffortJointInterface</hardwareInterface>
      <mechanicalReduction>1</mechanicalReduction>
    </actuator>
  </transmission>
  <transmission name="tran2">
    <type>transmission_interface/SimpleTransmission</type>
    <joint name="r_finger_joint">
      <hardwareInterface>hardware_interface/EffortJointInterface</hardwareInterface>
    </joint>
    <actuator name="motor2">
      <hardwareInterface>hardware_interface/EffortJointInterface</hardwareInterface>
      <mechanicalReduction>1</mechanicalReduction>
    </actuator>
  </transmission>
  <gazebo reference="gripper_base_link">
    <material>Gazebo/Gray</material>
    <mu1 value="0.2"/>
    <mu2 value="0.2"/>
    <selfCollide>false</selfCollide>
  </gazebo>
  <gazebo reference="l_finger_link">
    <material>Gazebo/Gray</material>
    <mu1 value="0.2"/>
    <mu2 value="0.2"/>
    <selfCollide>false</selfCollide>
  </gazebo>
  <gazebo reference="r_finger_link">
    <material>Gazebo/Gray</material>
    <mu1 value="0.2"/>
    <mu2 value="0.2"/>
    <selfCollide>false</selfCollide>
  </gazebo>
  <link name="r_base_link">
    <inertial>
      <origin rpy="0 0 0" xyz="-0.01 0.00 0.04"/>
      <mass value="0.027"/>
      <inertia ixx="0" ixy="0" ixz="0" iyy="0" iyz="0" izz="20"/>
    </inertial>
    <visual>
      <origin rpy="0 0 0" xyz="0 0 0"/>
      <geometry>
        <mesh filename="package://fingertest/meshes/base_link.STL"/>
      </geometry>
      <material name="">
        <color rgba="0.898039215686275 0.917647058823529 0.929411764705882 1"/>
      </material>
    </visual>
    <collision>
      <origin rpy="0 0 0" xyz="0 0 0"/>
      <geometry>
        <mesh filename="package://fingertest/meshes/base_link.STL"/>
      </geometry>
    </collision>
  </link>
  <link name="r_Link_1">
    <inertial>
      <origin rpy="0 0 0" xyz="0 -0.01 0.02"/>
      <mass value="0.02"/>
      <inertia ixx="0" ixy="0" ixz="0" iyy="0" iyz="0" izz="0"/>
    </inertial>
    <visual>
      <origin rpy="0 0 0" xyz="0 0 0"/>
      <geometry>
        <mesh filename="package://fingertest/meshes/Link_1.STL"/>
      </geometry>
      <material name="">
        <color rgba="0.898039215686275 0.917647058823529 0.929411764705882 1"/>
      </material>
    </visual>
    <collision>
      <origin rpy="0 0 0" xyz="0 0 0"/>
      <geometry>
        <mesh filename="package://fingertest/meshes/Link_1.STL"/>
      </geometry>
    </collision>
  </link>
  <!-- <link name="world"/> -->
  <joint name="r_fixed456" type="fixed">
    <origin rpy="0 0 0" xyz="-0.0264 0 0"/>
    <parent link="r_finger_link"/>
    <child link="r_base_link"/>
    <axis xyz="0 0 0"/>
  </joint>
  <joint name="r_Joint1" type="continuous">
    <origin rpy="0 -0.5235 0" xyz="-0.0165 0 0.0301"/>
    <parent link="r_base_link"/>
    <child link="r_Link_1"/>
    <axis xyz="0 -1 0"/>
  </joint>
  <link name="r_Link_2">
    <inertial>
      <origin rpy="0 0 0" xyz="0 -0.01 0.01"/>
      <mass value="0.0197910341256244"/>
      <inertia ixx="0" ixy="0" ixz="0" iyy="0" iyz="0" izz="0"/>
    </inertial>
    <visual>
      <origin rpy="0 0 0" xyz="0 0 0"/>
      <geometry>
        <mesh filename="package://fingertest/meshes/Link_2.STL"/>
      </geometry>
      <material name="">
        <color rgba="0.898039215686275 0.917647058823529 0.929411764705882 1"/>
      </material>
    </visual>
    <collision>
      <origin rpy="0 0 0" xyz="0 0 0"/>
      <geometry>
        <mesh filename="package://fingertest/meshes/Link_2.STL"/>
      </geometry>
    </collision>
  </link>
  <joint name="r_Joint2" type="continuous">
    <origin rpy="0 0 0" xyz="0 0 0.05715"/>
    <parent link="r_Link_1"/>
    <child link="r_Link_2"/>
    <axis xyz="0 -1 0"/>
  </joint>
  <link name="r_Link_3">
    <inertial>
      <origin rpy="0 0 0" xyz="-0.02 0.01 0.00"/>
      <mass value="0.027"/>
      <inertia ixx="0" ixy="0" ixz="0" iyy="0" iyz="0" izz="0"/>
    </inertial>
    <visual>
      <origin rpy="0 0 0" xyz="0 0 0"/>
      <geometry>
        <mesh filename="package://fingertest/meshes/Link_3.STL"/>
      </geometry>
      <material name="">
        <color rgba="0.898039215686275 0.917647058823529 0.929411764705882 1"/>
      </material>
    </visual>
    <collision name="bumper_r_collision">
      <origin rpy="0 0 0" xyz="0 0 0"/>
      <geometry name="bumper_r_collision">
        <mesh filename="package://fingertest/meshes/Link_3.STL"/>
      </geometry>
    </collision>
  </link>
  <joint name="r_Joint3" type="continuous">
    <origin rpy="0 0.5235 0" xyz="0 0 0.0381"/>
    <parent link="r_Link_2"/>
    <child link="r_Link_3"/>
    <axis xyz="0 -1 0"/>
  </joint>
  <transmission name="r_tran1">
    <type>transmission_interface/SimpleTransmission</type>
    <joint name="r_Joint1">
      <hardwareInterface>hardware_interface/EffortJointInterface</hardwareInterface>
    </joint>
    <actuator name="r_motor1">
      <hardwareInterface>hardware_interface/EffortJointInterface</hardwareInterface>
      <mechanicalReduction>1</mechanicalReduction>
    </actuator>
  </transmission>
  <transmission name="r_tran2">
    <type>transmission_interface/SimpleTransmission</type>
    <joint name="r_Joint2">
      <hardwareInterface>hardware_interface/EffortJointInterface</hardwareInterface>
    </joint>
    <actuator name="r_motor2">
      <hardwareInterface>hardware_interface/EffortJointInterface</hardwareInterface>
      <mechanicalReduction>1</mechanicalReduction>
    </actuator>
  </transmission>
  <transmission name="r_tran3">
    <type>transmission_interface/SimpleTransmission</type>
    <joint name="r_Joint3">
      <hardwareInterface>hardware_interface/EffortJointInterface</hardwareInterface>
    </joint>
    <actuator name="r_motor3">
      <hardwareInterface>hardware_interface/EffortJointInterface</hardwareInterface>
      <mechanicalReduction>1</mechanicalReduction>
    </actuator>
  </transmission>
  <gazebo reference="r_base_link">
    <material>Gazebo/White</material>
    <mu1 value="0.2"/>
    <mu2 value="0.2"/>
    <selfCollide>true</selfCollide>
  </gazebo>
  <gazebo reference="r_Link_1">
    <material>Gazebo/White</material>
    <mu1 value="0.2"/>
    <mu2 value="0.2"/>
    <selfCollide>true</selfCollide>
  </gazebo>
  <gazebo reference="r_Link_2">
    <material>Gazebo/White</material>
    <mu1 value="0.2"/>
    <mu2 value="0.2"/>
    <selfCollide>false</selfCollide>
  </gazebo>
  <gazebo reference="r_Link_3">
    <material>Gazebo/White</material>
    <mu1 value="0.2"/>
    <mu2 value="0.2"/>
    <selfCollide>true</selfCollide>
    <!-- <sensor name="${side}_Link_3_sensor" type="contact">
            <contact>
                <collision>bumper_${side}_collision_collison</collision>
            </contact>
            <plugin name="gazebo_ros_bumper_controller" filename="libgazebo_ros_bumper.so">
                <alwaysOn>true</alwaysOn>
                <updateRate>10.0</updateRate>
                <bumperTopicName>${side}_bumper_finger</bumperTopicName>
                <frameName>3fgripper</frameName>
            </plugin>
        </sensor> -->
  </gazebo>
  <!-- <gazebo reference="bumper_finger">
        <selfCollide>true</selfCollide>
        <sensor name="bumper_finger_sensor" type="contact">
            <contact>
                <collision>bumper_finger_collision_collison</collision>
            </contact>
            <plugin name="gazebo_ros_bumper_controller" filename="libgazebo_ros_bumper.so">
                <alwaysOn>true</alwaysOn>
                <updateRate>10.0</updateRate>
                <bumperTopicName>bumper_finger</bumperTopicName>
                <frameName>world</frameName>
            </plugin>
        </sensor>

    </gazebo> -->
  <gazebo reference="r_Link_3">
    <sensor name="r_Link_3_sensor" type="contact">
      <visualize>true</visualize>
      <always_on>true</always_on>
      <update_rate>50.0</update_rate>
      <contact>
        <collision>bumper_r_collision_collison</collision>
      </contact>
      <plugin filename="libgazebo_ros_bumper.so" name="gazebo_ros_bumper_controller">
        <alwaysOn>true</alwaysOn>
        <updateRate>10.0</updateRate>
        <bumperTopicName>r_bumper_finger</bumperTopicName>
        <frameName>world</frameName>
      </plugin>
    </sensor>
    <material>Gazebo/Red</material>
    <mu1>0.1</mu1>
    <mu2>0.1</mu2>
    <gravity>true</gravity>
    <selfCollide>false</selfCollide>
  </gazebo>
  <!-- <gazebo reference="bumper_finger">
        <selfCollide>true</selfCollide>
        <sensor name="bumper_finger_sensor" type="contact">
            <contact>
                <collision>bumper_finger_collision_collison</collision>
            </contact>
            <plugin name="gazebo_ros_bumper_controller" filename="libgazebo_ros_bumper.so">
                <alwaysOn>true</alwaysOn>
                <updateRate>10.0</updateRate>
                <bumperTopicName>bumper_finger</bumperTopicName>
                <frameName>world</frameName>
            </plugin>
        </sensor>
    </gazebo> -->
  <link name="l_base_link">
    <inertial>
      <origin rpy="0 0 0" xyz="-0.01 0.00 0.04"/>
      <mass value="0.027"/>
      <inertia ixx="0" ixy="0" ixz="0" iyy="0" iyz="0" izz="20"/>
    </inertial>
    <visual>
      <origin rpy="0 0 0" xyz="0 0 0"/>
      <geometry>
        <mesh filename="package://fingertest/meshes/base_link.STL"/>
      </geometry>
      <material name="">
        <color rgba="0.898039215686275 0.917647058823529 0.929411764705882 1"/>
      </material>
    </visual>
    <collision>
      <origin rpy="0 0 0" xyz="0 0 0"/>
      <geometry>
        <mesh filename="package://fingertest/meshes/base_link.STL"/>
      </geometry>
    </collision>
  </link>
  <link name="l_Link_1">
    <inertial>
      <origin rpy="0 0 0" xyz="0 -0.01 0.02"/>
      <mass value="0.02"/>
      <inertia ixx="0" ixy="0" ixz="0" iyy="0" iyz="0" izz="0"/>
    </inertial>
    <visual>
      <origin rpy="0 0 0" xyz="0 0 0"/>
      <geometry>
        <mesh filename="package://fingertest/meshes/Link_1.STL"/>
      </geometry>
      <material name="">
        <color rgba="0.898039215686275 0.917647058823529 0.929411764705882 1"/>
      </material>
    </visual>
    <collision>
      <origin rpy="0 0 0" xyz="0 0 0"/>
      <geometry>
        <mesh filename="package://fingertest/meshes/Link_1.STL"/>
      </geometry>
    </collision>
  </link>
  <!-- <link name="world"/> -->
  <joint name="l_fixed456" type="fixed">
    <origin rpy="0 0 0" xyz="-0.0264 0 0"/>
    <parent link="l_finger_link"/>
    <child link="l_base_link"/>
    <axis xyz="0 0 0"/>
  </joint>
  <joint name="l_Joint1" type="continuous">
    <origin rpy="0 -0.5235 0" xyz="-0.0165 0 0.0301"/>
    <parent link="l_base_link"/>
    <child link="l_Link_1"/>
    <axis xyz="0 -1 0"/>
  </joint>
  <link name="l_Link_2">
    <inertial>
      <origin rpy="0 0 0" xyz="0 -0.01 0.01"/>
      <mass value="0.0197910341256244"/>
      <inertia ixx="0" ixy="0" ixz="0" iyy="0" iyz="0" izz="0"/>
    </inertial>
    <visual>
      <origin rpy="0 0 0" xyz="0 0 0"/>
      <geometry>
        <mesh filename="package://fingertest/meshes/Link_2.STL"/>
      </geometry>
      <material name="">
        <color rgba="0.898039215686275 0.917647058823529 0.929411764705882 1"/>
      </material>
    </visual>
    <collision>
      <origin rpy="0 0 0" xyz="0 0 0"/>
      <geometry>
        <mesh filename="package://fingertest/meshes/Link_2.STL"/>
      </geometry>
    </collision>
  </link>
  <joint name="l_Joint2" type="continuous">
    <origin rpy="0 0 0" xyz="0 0 0.05715"/>
    <parent link="l_Link_1"/>
    <child link="l_Link_2"/>
    <axis xyz="0 -1 0"/>
  </joint>
  <link name="l_Link_3">
    <inertial>
      <origin rpy="0 0 0" xyz="-0.02 0.01 0.00"/>
      <mass value="0.027"/>
      <inertia ixx="0" ixy="0" ixz="0" iyy="0" iyz="0" izz="0"/>
    </inertial>
    <visual>
      <origin rpy="0 0 0" xyz="0 0 0"/>
      <geometry>
        <mesh filename="package://fingertest/meshes/Link_3.STL"/>
      </geometry>
      <material name="">
        <color rgba="0.898039215686275 0.917647058823529 0.929411764705882 1"/>
      </material>
    </visual>
    <collision name="bumper_l_collision">
      <origin rpy="0 0 0" xyz="0 0 0"/>
      <geometry name="bumper_l_collision">
        <mesh filename="package://fingertest/meshes/Link_3.STL"/>
      </geometry>
    </collision>
  </link>
  <joint name="l_Joint3" type="continuous">
    <origin rpy="0 0.5235 0" xyz="0 0 0.0381"/>
    <parent link="l_Link_2"/>
    <child link="l_Link_3"/>
    <axis xyz="0 -1 0"/>
  </joint>
  <transmission name="l_tran1">
    <type>transmission_interface/SimpleTransmission</type>
    <joint name="l_Joint1">
      <hardwareInterface>hardware_interface/EffortJointInterface</hardwareInterface>
    </joint>
    <actuator name="l_motor1">
      <hardwareInterface>hardware_interface/EffortJointInterface</hardwareInterface>
      <mechanicalReduction>1</mechanicalReduction>
    </actuator>
  </transmission>
  <transmission name="l_tran2">
    <type>transmission_interface/SimpleTransmission</type>
    <joint name="l_Joint2">
      <hardwareInterface>hardware_interface/EffortJointInterface</hardwareInterface>
    </joint>
    <actuator name="l_motor2">
      <hardwareInterface>hardware_interface/EffortJointInterface</hardwareInterface>
      <mechanicalReduction>1</mechanicalReduction>
    </actuator>
  </transmission>
  <transmission name="l_tran3">
    <type>transmission_interface/SimpleTransmission</type>
    <joint name="l_Joint3">
      <hardwareInterface>hardware_interface/EffortJointInterface</hardwareInterface>
    </joint>
    <actuator name="l_motor3">
      <hardwareInterface>hardware_interface/EffortJointInterface</hardwareInterface>
      <mechanicalReduction>1</mechanicalReduction>
    </actuator>
  </transmission>
  <gazebo reference="l_base_link">
    <material>Gazebo/White</material>
    <mu1 value="0.2"/>
    <mu2 value="0.2"/>
    <selfCollide>true</selfCollide>
  </gazebo>
  <gazebo reference="l_Link_1">
    <material>Gazebo/White</material>
    <mu1 value="0.2"/>
    <mu2 value="0.2"/>
    <selfCollide>true</selfCollide>
  </gazebo>
  <gazebo reference="l_Link_2">
    <material>Gazebo/White</material>
    <mu1 value="0.2"/>
    <mu2 value="0.2"/>
    <selfCollide>false</selfCollide>
  </gazebo>
  <gazebo reference="l_Link_3">
    <material>Gazebo/White</material>
    <mu1 value="0.2"/>
    <mu2 value="0.2"/>
    <selfCollide>true</selfCollide>
    <!-- <sensor name="${side}_Link_3_sensor" type="contact">
            <contact>
                <collision>bumper_${side}_collision_collison</collision>
            </contact>
            <plugin name="gazebo_ros_bumper_controller" filename="libgazebo_ros_bumper.so">
                <alwaysOn>true</alwaysOn>
                <updateRate>10.0</updateRate>
                <bumperTopicName>${side}_bumper_finger</bumperTopicName>
                <frameName>3fgripper</frameName>
            </plugin>
        </sensor> -->
  </gazebo>
  <!-- <gazebo reference="bumper_finger">
        <selfCollide>true</selfCollide>
        <sensor name="bumper_finger_sensor" type="contact">
            <contact>
                <collision>bumper_finger_collision_collison</collision>
            </contact>
            <plugin name="gazebo_ros_bumper_controller" filename="libgazebo_ros_bumper.so">
                <alwaysOn>true</alwaysOn>
                <updateRate>10.0</updateRate>
                <bumperTopicName>bumper_finger</bumperTopicName>
                <frameName>world</frameName>
            </plugin>
        </sensor>

    </gazebo> -->
  <gazebo reference="l_Link_3">
    <sensor name="l_Link_3_sensor" type="contact">
      <visualize>true</visualize>
      <always_on>true</always_on>
      <update_rate>50.0</update_rate>
      <contact>
        <collision>bumper_l_collision_collison</collision>
      </contact>
      <plugin filename="libgazebo_ros_bumper.so" name="gazebo_ros_bumper_controller">
        <alwaysOn>true</alwaysOn>
        <updateRate>10.0</updateRate>
        <bumperTopicName>l_bumper_finger</bumperTopicName>
        <frameName>world</frameName>
      </plugin>
    </sensor>
    <material>Gazebo/Red</material>
    <mu1>0.1</mu1>
    <mu2>0.1</mu2>
    <gravity>true</gravity>
    <selfCollide>false</selfCollide>
  </gazebo>
  <!-- <gazebo reference="bumper_finger">
        <selfCollide>true</selfCollide>
        <sensor name="bumper_finger_sensor" type="contact">
            <contact>
                <collision>bumper_finger_collision_collison</collision>
            </contact>
            <plugin name="gazebo_ros_bumper_controller" filename="libgazebo_ros_bumper.so">
                <alwaysOn>true</alwaysOn>
                <updateRate>10.0</updateRate>
                <bumperTopicName>bumper_finger</bumperTopicName>
                <frameName>world</frameName>
            </plugin>
        </sensor>
    </gazebo> -->
  <link name="m_base_link">
    <inertial>
      <origin rpy="0 0 0" xyz="-0.01 0.00 0.04"/>
      <mass value="0.027"/>
      <inertia ixx="0" ixy="0" ixz="0" iyy="0" iyz="0" izz="20"/>
    </inertial>
    <visual>
      <origin rpy="0 0 0" xyz="0 0 0"/>
      <geometry>
        <mesh filename="package://fingertest/meshes/base_link.STL"/>
      </geometry>
      <material name="">
        <color rgba="0.898039215686275 0.917647058823529 0.929411764705882 1"/>
      </material>
    </visual>
    <collision>
      <origin rpy="0 0 0" xyz="0 0 0"/>
      <geometry>
        <mesh filename="package://fingertest/meshes/base_link.STL"/>
      </geometry>
    </collision>
  </link>
  <link name="m_Link_1">
    <inertial>
      <origin rpy="0 0 0" xyz="0 -0.01 0.02"/>
      <mass value="0.02"/>
      <inertia ixx="0" ixy="0" ixz="0" iyy="0" iyz="0" izz="0"/>
    </inertial>
    <visual>
      <origin rpy="0 0 0" xyz="0 0 0"/>
      <geometry>
        <mesh filename="package://fingertest/meshes/Link_1.STL"/>
      </geometry>
      <material name="">
        <color rgba="0.898039215686275 0.917647058823529 0.929411764705882 1"/>
      </material>
    </visual>
    <collision>
      <origin rpy="0 0 0" xyz="0 0 0"/>
      <geometry>
        <mesh filename="package://fingertest/meshes/Link_1.STL"/>
      </geometry>
    </collision>
  </link>
  <!-- <link name="world"/> -->
  <joint name="m_fixed456" type="fixed">
    <origin rpy="0 0 3.14" xyz="0.0264 0 0.0565"/>
    <parent link="gripper_base_link"/>
    <child link="m_base_link"/>
    <axis xyz="0 0 0"/>
  </joint>
  <joint name="m_Joint1" type="continuous">
    <origin rpy="0 -0.5235 0" xyz="-0.0165 0 0.0301"/>
    <parent link="m_base_link"/>
    <child link="m_Link_1"/>
    <axis xyz="0 -1 0"/>
  </joint>
  <link name="m_Link_2">
    <inertial>
      <origin rpy="0 0 0" xyz="0 -0.01 0.01"/>
      <mass value="0.0197910341256244"/>
      <inertia ixx="0" ixy="0" ixz="0" iyy="0" iyz="0" izz="0"/>
    </inertial>
    <visual>
      <origin rpy="0 0 0" xyz="0 0 0"/>
      <geometry>
        <mesh filename="package://fingertest/meshes/Link_2.STL"/>
      </geometry>
      <material name="">
        <color rgba="0.898039215686275 0.917647058823529 0.929411764705882 1"/>
      </material>
    </visual>
    <collision>
      <origin rpy="0 0 0" xyz="0 0 0"/>
      <geometry>
        <mesh filename="package://fingertest/meshes/Link_2.STL"/>
      </geometry>
    </collision>
  </link>
  <joint name="m_Joint2" type="continuous">
    <origin rpy="0 0 0" xyz="0 0 0.05715"/>
    <parent link="m_Link_1"/>
    <child link="m_Link_2"/>
    <axis xyz="0 -1 0"/>
  </joint>
  <link name="m_Link_3">
    <inertial>
      <origin rpy="0 0 0" xyz="-0.02 0.01 0.00"/>
      <mass value="0.027"/>
      <inertia ixx="0" ixy="0" ixz="0" iyy="0" iyz="0" izz="0"/>
    </inertial>
    <visual>
      <origin rpy="0 0 0" xyz="0 0 0"/>
      <geometry>
        <mesh filename="package://fingertest/meshes/Link_3.STL"/>
      </geometry>
      <material name="">
        <color rgba="0.898039215686275 0.917647058823529 0.929411764705882 1"/>
      </material>
    </visual>
    <collision name="bumper_m_collision">
      <origin rpy="0 0 0" xyz="0 0 0"/>
      <geometry name="bumper_m_collision">
        <mesh filename="package://fingertest/meshes/Link_3.STL"/>
      </geometry>
    </collision>
  </link>
  <joint name="m_Joint3" type="continuous">
    <origin rpy="0 0.5235 0" xyz="0 0 0.0381"/>
    <parent link="m_Link_2"/>
    <child link="m_Link_3"/>
    <axis xyz="0 -1 0"/>
  </joint>
  <transmission name="m_tran1">
    <type>transmission_interface/SimpleTransmission</type>
    <joint name="m_Joint1">
      <hardwareInterface>hardware_interface/EffortJointInterface</hardwareInterface>
    </joint>
    <actuator name="m_motor1">
      <hardwareInterface>hardware_interface/EffortJointInterface</hardwareInterface>
      <mechanicalReduction>1</mechanicalReduction>
    </actuator>
  </transmission>
  <transmission name="m_tran2">
    <type>transmission_interface/SimpleTransmission</type>
    <joint name="m_Joint2">
      <hardwareInterface>hardware_interface/EffortJointInterface</hardwareInterface>
    </joint>
    <actuator name="m_motor2">
      <hardwareInterface>hardware_interface/EffortJointInterface</hardwareInterface>
      <mechanicalReduction>1</mechanicalReduction>
    </actuator>
  </transmission>
  <transmission name="m_tran3">
    <type>transmission_interface/SimpleTransmission</type>
    <joint name="m_Joint3">
      <hardwareInterface>hardware_interface/EffortJointInterface</hardwareInterface>
    </joint>
    <actuator name="m_motor3">
      <hardwareInterface>hardware_interface/EffortJointInterface</hardwareInterface>
      <mechanicalReduction>1</mechanicalReduction>
    </actuator>
  </transmission>
  <gazebo reference="m_base_link">
    <material>Gazebo/White</material>
    <mu1 value="0.2"/>
    <mu2 value="0.2"/>
    <selfCollide>true</selfCollide>
  </gazebo>
  <gazebo reference="m_Link_1">
    <material>Gazebo/White</material>
    <mu1 value="0.2"/>
    <mu2 value="0.2"/>
    <selfCollide>true</selfCollide>
  </gazebo>
  <gazebo reference="m_Link_2">
    <material>Gazebo/White</material>
    <mu1 value="0.2"/>
    <mu2 value="0.2"/>
    <selfCollide>false</selfCollide>
  </gazebo>
  <gazebo reference="m_Link_3">
    <material>Gazebo/White</material>
    <mu1 value="0.2"/>
    <mu2 value="0.2"/>
    <selfCollide>true</selfCollide>
    <!-- <sensor name="${side}_Link_3_sensor" type="contact">
            <contact>
                <collision>bumper_${side}_collision_collison</collision>
            </contact>
            <plugin name="gazebo_ros_bumper_controller" filename="libgazebo_ros_bumper.so">
                <alwaysOn>true</alwaysOn>
                <updateRate>10.0</updateRate>
                <bumperTopicName>${side}_bumper_finger</bumperTopicName>
                <frameName>3fgripper</frameName>
            </plugin>
        </sensor> -->
  </gazebo>
  <!-- <gazebo reference="bumper_finger">
        <selfCollide>true</selfCollide>
        <sensor name="bumper_finger_sensor" type="contact">
            <contact>
                <collision>bumper_finger_collision_collison</collision>
            </contact>
            <plugin name="gazebo_ros_bumper_controller" filename="libgazebo_ros_bumper.so">
                <alwaysOn>true</alwaysOn>
                <updateRate>10.0</updateRate>
                <bumperTopicName>bumper_finger</bumperTopicName>
                <frameName>world</frameName>
            </plugin>
        </sensor>

    </gazebo> -->
  <gazebo reference="m_Link_3">
    <sensor name="m_Link_3_sensor" type="contact">
      <visualize>true</visualize>
      <always_on>true</always_on>
      <update_rate>50.0</update_rate>
      <contact>
        <collision>bumper_m_collision_collison</collision>
      </contact>
      <plugin filename="libgazebo_ros_bumper.so" name="gazebo_ros_bumper_controller">
        <alwaysOn>true</alwaysOn>
        <updateRate>10.0</updateRate>
        <bumperTopicName>m_bumper_finger</bumperTopicName>
        <frameName>world</frameName>
      </plugin>
    </sensor>
    <material>Gazebo/Red</material>
    <mu1>0.1</mu1>
    <mu2>0.1</mu2>
    <gravity>true</gravity>
    <selfCollide>false</selfCollide>
  </gazebo>
  <!-- <gazebo reference="bumper_finger">
        <selfCollide>true</selfCollide>
        <sensor name="bumper_finger_sensor" type="contact">
            <contact>
                <collision>bumper_finger_collision_collison</collision>
            </contact>
            <plugin name="gazebo_ros_bumper_controller" filename="libgazebo_ros_bumper.so">
                <alwaysOn>true</alwaysOn>
                <updateRate>10.0</updateRate>
                <bumperTopicName>bumper_finger</bumperTopicName>
                <frameName>world</frameName>
            </plugin>
        </sensor>
    </gazebo> -->
</robot>

